Workbook

Sheet DP Addendum
A1: DP Addendum Last updated: June 2026
A3: Complete all gray areas of this form as thoroughly as possible and attach to your agency's budget submission via Agency Budget System.
A5: Section One: Current Facility Information and Utilization
A7: UFI Number | C7: Lease Number | G7: Square Feet | I7: Lease End Date | K7: City
A8: UFI Number | C8: Lease Number | G8: Square Feet | I8: Lease End Date | K8: City
A9: UFI Number | C9: Lease Number | G9: Square Feet | I9: Lease End Date | K9: City
G10: Total Square Feet | H10: =SUM(H7:H9) -> 0
G11: Total Office Facility Efficiency | H11: =IFERROR((L76-H10)/L76,0) -> 0 | L11: Total Annual Cost
K12: Annual Cost per Square Foot Year | M12: =IFERROR($M$11/$H$10,0) -> 0
A13: User Space Allocation | C13: Fully Remote | D13: Externally Mobile | F13: Resident | G13: Total
A14: Count | G14: =SUM(C14:F14) -> 0 | I14: *Information will be verified by OFM. | K14: Total Square Footage Per User | M14: =IFERROR(H10/G14,0) -> 0
A15: *Refer to Reference Tables tab for user type definitions.
A17: Sublease Information
A19: UFI Number | C19: Sublease Number | G19: Sublease Square Feet | I19: Sublease End Date | L19: Receivable Income
A20: UFI Number | C20: Sublease Number | G20: Sublease Square Feet | I20: Sublease End Date | L20: Receivable Income
A21: UFI Number | C21: Sublease Number | G21: Sublease Square Feet | I21: Sublease End Date | L21: Receivable Income
A23: Section Two: Project Information
C25: Is this project a colocation with another agency? | I25: Requested County
C26: If yes, which agency? | I26: Requested City
C27: Primary Space Type | I27: Requested Effective Start Date
C28: Secondary Space Type | I28: Requested Lease Term (Years)
I29: Cancellation Clause Required
A31: Does your agency have existing facilities in the area? If so, how does this influence your decision to move forward with the above project type?
A38: Section Three: Costs
A39: Populate agency requested one-time costs in gray fields. Agency may use OFM auto-populated assumptions located on the "Reference Tables" tab.
A40: Total One-Time Cost | C40: DES Fees | D40: Tenant Improvement | F40: Technology Infrastructure | G40: New Furniture | I40: Relocation Furniture | J40: Moving Staff | K40: Building Security | L40: EV Expense | M40: Other
A41: =ROUND(SUM($C$41:$M$41),-3) -> 0
A42: Agency One-Time Cost Assumptions
A47: If the facility is leaving inventory and not being relocated or replaced, stop here. 🛑
A49: Projected Annual Costs
A50: OFM Office Space Market Rate | C50: Lease Cost (Market Rate X SF) | E50: Other | G50: Subtotal | I50: Additional Parking | J50: Total Annual Cost | L50: Annual Cost per Square Foot
A51: *Cost per square foot per year
C52: =$A$52*$L$76 -> 0 | G52: =SUM(C52:F52) -> 0 | I52: 0 | J52: =SUM(G52:I52) -> 0 | L52: =IFERROR($J$52/$L$76,0) -> 0
A55: Section Four: Space Allocation
A56: This tool will calculate total allocated square footage and total square footage per user. Please use the Telework Schedule Crosswalk tables on the "Reference Tables" Tab. If your agency requires program-specific space beyond the standard allocation, enter the type of space and desired square footage, which will be added to the baseline allocation. Agencies must justify the need for any program-specific spaces. If allocation is over 20,000 sq ft provide the Life Cycle Cost Model Tool as an addendum to this form.
Q57: D
A61: Baseline User Space Allocation | C61: Count | D61: SQ FT | F61: Percent of SQ FT per user type | H61: Program Specific Spaces | L61: SQ FT
A62: Fully Remote | D62: =C62*'Reference Tables'!C27 -> 0 | F62: =IFERROR(D62/D65,0) -> 0
A63: Externally Mobile | D63: =C63*'Reference Tables'!D27 -> 0 | F63: =IFERROR(D63/D65,0) -> 0
A64: Resident | D64: =C64*'Reference Tables'!F27 -> 0 | F64: =IFERROR(D64/D65,0) -> 0
...

Sheet Reference Tables
A1: Reference Tables
A6: Telework Crosswalk 8-Hour Days | N6: User Type and (HRMS Telework EE Code)* | P6: MyPortal Telework Participation (One Week Period) | T6: 9-Hour Days | X6: 10-Hour Days
A7: User Type and (HRMS Telework EE Code)* | C7: MyPortal Telework Participation (One Week Period) | H7: 8-Hour Days | T7: Planned Days in Office (Every Two Weeks) | W7: % in Office (Every Two Weeks) | X7: Planned Days in Office (Every Two Weeks) | Z7: % in Office (Every Two Weeks)
H8: Planned Days in Office (Every Two Weeks) | K8: % in Office (Every Two Weeks) | N8: Fully Remote (EP9) | P8: Full time/Near full time remote | T8: 0 regularly scheduled days | W8: 0 | X8: 0 regularly scheduled days | Z8: 0
A9: Fully Remote (EP9) | C9: Full time/Near full time remote | H9: 0 regularly scheduled days | K9: 0 | N9: Externally Mobile (EP8) | P9: 4 | T9: 1 | W9: 0.11 | X9: 0 | Z9: 0
A10: Externally Mobile (EP8) | C10: 4 | H10: 2 | K10: 0.2 | N10: Externally Mobile (EP7) | P10: 3 | T10: 3 | W10: 0.33 | X10: 2 | Z10: 0.25
A11: Externally Mobile (EP7) | C11: 3 | H11: 4 | K11: 0.4 | N11: Externally Mobile (EP6)** | P11: 2 | T11: 5 | W11: 0.56 | X11: 4 | Z11: 0.5
A12: Resident (EP6)** | C12: 2 | H12: 6 | K12: 0.6 | N12: Resident (EP5) | P12: 1 | T12: 7 | W12: 0.78 | X12: 6 | Z12: 0.75
A13: Resident (EP5) | C13: 1 | H13: 8 | K13: 0.8 | N13: Resident (EP0) | P13: Less than one day/ ad hoc | T13: 8 | W13: 0.89 | X13: 7 | Z13: 0.88
A14: Resident (EP0) | C14: Less than one day/ad hoc | H14: 9 | K14: 0.9 | N14: Resident (NP) | P14: Not Participating | T14: 9 | W14: 1 | X14: 8 | Z14: 1
A15: Resident (NP) | C15: Not Participating | H15: 10 | K15: 1
A17: *Refer to the HRMS data definitions resource guide, Telework (EE), to view the Telework code definitions. Be aware that HRMS captures the time spent teleworking, whereas OFM Facilities Oversight policy refers to the time spent in the office.
A18: *HRMS Telework EE Code EP6 may be categized as Resident or Externally Mobile depending on the work schedule.
A21: Standards | C21: Fully Remote | D21: Externally Mobile | F21: Resident
A23: User space | C23: 0 | D23: =F23/3 -> 26.333333 | F23: 79
A24: Conference/shared spaces | C24: 0 | D24: =F24/3 -> 13.333333 | F24: 40
A25: Circulation=40% of spaces | C25: 0 | D25: =F25/3 -> 15.866667 | F25: =SUM(F23:F24)*0.4 -> 47.6
A26: Building Services=15% total | C26: 0 | D26: =F26/3 -> 8.33 | F26: =SUM(F23:F25)*0.15 -> 24.99
A27: Rentable Square Footage Per User (rounded to next square foot) | C27: =SUM(C23:C26) -> 0 | D27: =ROUND(SUM($D$23:$E$26),0) -> 64 | F27: =ROUND(SUM($F$23:$F$26),0) -> 192
A30: Total One-Time Cost | C30: DES Fees | D30: Tenant Improvement | F30: Technology Infrastructure | G30: New Furniture | I30: Relocation Furniture | J30: Moving Staff | K30: Building Security | L30: EV Expense | M30: Other
A31: =ROUND(SUM($C$31:$M$31),-3) -> 0 | C31: =IF(SUM('DP Addendum'!L76:M76)<>0,ROUND(IF(SUM('DP Addendum'!L76:M76)<=4999,189*40,IF(SUM('DP Addendum'!J28:L28)=5,SUM('DP Addendum'!L76:M76)*5*0.25,IF(SUM('DP Addendum'!J28:L28)=10,(SUM('DP Addendum'!L76:M76)*5*0.25)+(SUM('DP Addendum'!L76:M76)*5*0.125),0))),-2),0) -> 0 | D31: =ROUND(SUM('DP Addendum'!L76:M76)*100,-2) -> 0 | F31: =ROUND(SUM('DP Addendum'!C68:D70)*1500,-2) -> 0 | G31: 0 | I31: =ROUND(SUM('DP Addendum'!C68:D70)*450,-2) -> 0 | J31: =ROUND((SUM('DP Addendum'!C63:C64)*300),-2) -> 0 | K31: =ROUND(IF(SUM('DP Addendum'!L76:M76)=0,"$0",IF(SUM('DP Addendum'!L76:M76)<=5000,"$5,000",IF(SUM('DP Addendum'!L76:M76)<=20000,"$10,000",IF(SUM('DP Addendum'!L76:M76)<=40000,"$20,000",IF(SUM('DP Addendum'!L76:M76)<=50000,"$30,000",IF(SUM('DP Addendum'!L76:M76)>50000,"$40,000","")))))),-2) -> 0
A32: *These costs will automatically calculate with OFM cost assumptions once the proposed information is entered on the DP Addendum Form.
